<?xml version="1.0" ?>
<robot xmlns:xacro="http://www.ros.org/wiki/xacro">
  <xacro:macro name="caster_back_joint_macro"
               params="caster_back parent
                       x y z roll pitch yaw">
    <joint name="${caster_back}_joint" type="continuous">
      <parent link="${parent}_link"/>
      <child  link="${caster_back}_link"/>
      <origin xyz="${x} ${y} ${z}" rpy="${roll} ${pitch} ${yaw}"/>
      <axis xyz="1 0 0"/>
    </joint>
  </xacro:macro>

  <xacro:macro name="caster_back_link_macro"
               params="caster_back
                       x y z roll pitch yaw">
    <xacro:property name="MESH_FILE" value="package://vehicle/xacro/meshes/tire.dae"/>
    <xacro:property name="SCALE" value="0.10"/>
    <link name="${caster_back}_link">
      <visual>
        <origin xyz="${x} ${y} ${z}" rpy="${roll} ${pitch} ${yaw}"/>
        <geometry>
          <mesh filename="${MESH_FILE}" scale="${SCALE} ${SCALE} ${SCALE}"/>
        </geometry>
      </visual>
      <collision>
        <origin xyz="${x} ${y} ${z}" rpy="${roll} ${pitch} ${yaw}"/>
        <geometry>
          <mesh filename="${MESH_FILE}" scale="${SCALE} ${SCALE} ${SCALE}"/>
        </geometry>
        <!-- <origin xyz="0.0  0.001  0.0" rpy="0.0  0.0  0.0"/>
        <geometry>
          <box size="0.030  0.009  0.020"/>
        </geometry> -->
      </collision>
      <inertial>
        <origin xyz="${x} ${y} ${z}" rpy="${roll} ${pitch} ${yaw}"/>
        <mass value="0.005" />
        <inertia ixx="0.001" ixy="0.0" ixz="0.0" iyy="0.001" iyz="0.0" izz="0.001"/>
        <!-- <mass value="5.0" />
        <inertia ixx="0.01517" ixy="0.0" ixz="0.0" iyy="0.01517" iyz="0.0" izz="0.02500"/> -->
      </inertial>
    </link>
  </xacro:macro>  
</robot>
