<?xml version="1.0" ?>
<robot xmlns:xacro="http://www.ros.org/wiki/xacro">
  <xacro:macro name="wheel_joint_macro"
               params="wheel parent
                       x y z roll pitch yaw">
    <joint name="${wheel}_joint" type="continuous">
      <parent link="${parent}_link"/>
      <child  link="${wheel}_link"/>
      <origin xyz="${x} ${y} ${z}" rpy="${roll} ${pitch} ${yaw}"/>
      <axis xyz="1 0 0"/>
    </joint>
  </xacro:macro>

  <xacro:macro name="wheel_link_macro"
               params="wheel
                       x y z roll pitch yaw">
    <xacro:property name="MESH_FILE" value="package://vehicle/xacro/meshes/tire.dae"/>
    <xacro:property name="THICKNESS_SCALE" value="0.05"/>
    <xacro:property name="SIZE_SCALE" value="0.12"/>
    <link name="${wheel}_link">
      <visual>
        <origin xyz="${x} ${y} ${z}" rpy="${roll} ${pitch} ${yaw}"/>
        <geometry>
          <mesh filename="${MESH_FILE}" scale="${THICKNESS_SCALE} ${SIZE_SCALE} ${SIZE_SCALE}"/>
        </geometry>
      </visual>
      <collision>
        <origin xyz="${x} ${y} ${z}" rpy="${roll} ${pitch} ${yaw}"/>
        <geometry>
          <mesh filename="${MESH_FILE}" scale="${THICKNESS_SCALE} ${SIZE_SCALE} ${SIZE_SCALE}"/>
        </geometry>
      </collision>
      <inertial>
        <origin xyz="${x} ${y} ${z}" rpy="${roll} ${pitch} ${yaw}"/>
        <mass value="7.0" />
        <inertia ixx="0.04778" ixy="0.000" ixz="0.000" iyy="0.04778" iyz="0.000" izz="0.07875"/>
      </inertial>
    </link>
  </xacro:macro>  
</robot>
